<?xml version="1.0"?>
<robot name="origins">
  <link name="base_link">
    <visual>
      <geometry>
        <cylinder length="0.01" radius="0.05"/>
      </geometry>
      <origin rpy="0 0 0" xyz="0 0 0.01"/>
    </visual>
  </link>
  <link name="link1">
    <visual>
      <geometry>
        <cylinder length="0.095" radius="0.03"/>
      </geometry>
      <origin rpy="0 0 0" xyz="0 0 0.045"/>
    </visual>
  </link>
  <joint name="base_link_link1" type="revolute">
    <parent link="base_link"/>
    <child link="link1"/>
    <axis xyz="0 0 1"/>
    <limit effort="1000.0" lower="-1.57" upper="1.57" velocity="0.5"/>
    <origin rpy="0 0 0" xyz="0 0 0.01"/>
  </joint>
<link name="link2">
    <visual>
      <geometry>
        <cylinder length="0.12" radius="0.015"/>
      </geometry>
      <origin rpy="0 -1.57 0" xyz="-0.075 0 0"/>
    </visual>
  </link>
  <joint name="link1_link2" type="revolute">
    <parent link="link1"/>
    <child link="link2"/>
    <origin rpy="0 1.57 0" xyz="0 0.033 0.095"/>
    <limit effort="1000.0" lower="-2.57" upper="2.5" velocity="0.5"/>
    <axis xyz="0 0 1"/>
  </joint>
<link name="link3">
    <visual>
      <geometry>
	<box size="0.04 0.06 0.04"/>
      </geometry>
      <origin rpy="0 0 0" xyz="-0.02 0 0"/>
    </visual>
  </link>
  <joint name="link2_link3" type="revolute">
    <parent link="link2"/>
    <child link="link3"/>
    <origin rpy="0 0 0" xyz="-0.12 0 0"/>
    <limit effort="1000.0" lower="-2.0" upper="2.0" velocity="0.5"/>
    <axis xyz="0 0 1"/>
  </joint>
<link name="link4">
    <visual>
      <geometry>
        <cylinder length="0.133" radius="0.01"/>
      </geometry>
      <origin rpy="0 0 0" xyz="0 0 0.0665"/>
    </visual>
  </link>
  <joint name="link3_link4" type="revolute">
    <parent link="link3"/>
    <child link="link4"/>
    <origin rpy="-1.57 0 0" xyz="-0.02 0 0"/>
    <limit effort="1000.0" lower="-1.57" upper="1.57" velocity="0.5"/>
    <axis xyz="0 0 1"/>
  </joint>
<link name="link5">
    <visual>
      <geometry>
	<box size="0.04 0.02 0.03"/>
      </geometry>
      <origin rpy="0 0 1.57" xyz="0 0 0"/>
    </visual>
  </link>
  <joint name="link4_link5" type="revolute">
    <parent link="link4"/>
    <child link="link5"/>
    <origin rpy="0 -1.57 0" xyz="0 0 0.133"/>
    <limit effort="1000.0" lower="-1.57" upper="1.57" velocity="0.5"/>
    <axis xyz="0 0 1"/>
  </joint>
<link name="link6">
    <visual>
      <geometry>
        <cylinder length="0.005" radius="0.015"/>
      </geometry>
      <origin rpy="0 0 0" xyz="0 0 -0.0025"/>
    </visual>
  </link>
  <joint name="link5_link6" type="revolute">
    <parent link="link5"/>
    <child link="link6"/>
    <origin rpy="0 1.57 0" xyz="0.03 0 0"/>
    <limit effort="1000.0" lower="1.57" upper="-1.57" velocity="0.5"/>
    <axis xyz="0 0 1"/>
  </joint>
<!--  
  <link name="link3">
    <visual>
      <geometry>
        <cylinder length="0.15" radius="0.01"/>
      </geometry>
      <origin rpy="0 0 0" xyz="0 0 0.075"/>
    </visual>
  </link>
  <joint name="link2_link3" type="revolute">
    <parent link="link2"/>
    <child link="link3"/>
    <origin rpy="0 0 0" xyz="0 0 0.2"/>
    <limit effort="1000.0" lower="-2.53" upper="0" velocity="0.5"/>
    <axis xyz="1 0 0"/>
    <origin rpy="0 0 0" xyz="0 0 0.02"/>
  </joint>
  <link name="link4">
    <visual>
      <geometry>
        <cylinder length="0.015" radius="0.02"/>
      </geometry>
      <origin rpy="0 0 0" xyz="0 0 0"/>
    </visual>
  </link>
  <joint name="link3_link4" type="fixed">
    <parent link="link3"/>
    <child link="link4"/>
    <origin rpy="0 0 0" xyz="0 0 0.15"/>
    <axis xyz="0 0 0"/>
  </joint>
-->
</robot>
